WARNING 2024-09-11 15:55:28,419 django.request.log_response:241- Not Found: /favicon.ico
WARNING 2024-09-11 16:19:38,036 django.request.log_response:241- Not Found: /favicon.ico
WARNING 2024-09-11 16:21:15,567 django.request.log_response:241- Not Found: /favicon.ico
WARNING 2024-09-11 16:33:53,635 django.request.log_response:241- Not Found: /accounts/
WARNING 2024-09-11 16:33:53,638 django.channels.server.log_action:176- HTTP GET /accounts/ 404 [0.29, 172.19.0.1:56800]
WARNING 2024-09-11 16:33:53,843 django.request.log_response:241- Not Found: /favicon.ico
WARNING 2024-09-11 16:33:53,845 django.channels.server.log_action:176- HTTP GET /favicon.ico 404 [0.13, 172.19.0.1:56810]
WARNING 2024-09-11 16:52:38,639 django.request.log_response:241- Not Found: /favicon.ico
WARNING 2024-09-11 16:53:57,595 django.request.log_response:241- Not Found: /favicon.ico
ERROR 2024-09-12 14:33:34,972 django.request.log_response:241- Internal Server Error: /
Traceback (most recent call last):
  File "/usr/local/lib/python3.8/site-packages/django/core/handlers/exception.py", line 55, in inner
    response = get_response(request)
  File "/usr/local/lib/python3.8/site-packages/django/core/handlers/base.py", line 197, in _get_response
    response = wrapped_callback(request, *callback_args, **callback_kwargs)
  File "/usr/local/lib/python3.8/site-packages/django/views/generic/base.py", line 104, in view
    return self.dispatch(request, *args, **kwargs)
  File "/usr/local/lib/python3.8/site-packages/django/views/generic/base.py", line 143, in dispatch
    return handler(request, *args, **kwargs)
  File "/app/home/views.py", line 41, in get
    "stock": self.get_finance_data("ETH-USD"),
  File "/app/home/views.py", line 48, in get_finance_data
    df["Date"] = df["Date"].dt.strftime("%m/%d")
  File "/usr/local/lib/python3.8/site-packages/pandas/core/generic.py", line 5989, in __getattr__
    return object.__getattribute__(self, name)
  File "/usr/local/lib/python3.8/site-packages/pandas/core/accessor.py", line 224, in __get__
    accessor_obj = self._accessor(obj)
  File "/usr/local/lib/python3.8/site-packages/pandas/core/indexes/accessors.py", line 580, in __new__
    raise AttributeError("Can only use .dt accessor with datetimelike values")
AttributeError: Can only use .dt accessor with datetimelike values
WARNING 2024-09-12 14:33:41,777 django.request.log_response:241- Not Found: /favicon.ico
ERROR 2024-09-12 14:33:48,852 django.request.log_response:241- Internal Server Error: /
Traceback (most recent call last):
  File "/usr/local/lib/python3.8/site-packages/django/core/handlers/exception.py", line 55, in inner
    response = get_response(request)
  File "/usr/local/lib/python3.8/site-packages/django/core/handlers/base.py", line 197, in _get_response
    response = wrapped_callback(request, *callback_args, **callback_kwargs)
  File "/usr/local/lib/python3.8/site-packages/django/views/generic/base.py", line 104, in view
    return self.dispatch(request, *args, **kwargs)
  File "/usr/local/lib/python3.8/site-packages/django/views/generic/base.py", line 143, in dispatch
    return handler(request, *args, **kwargs)
  File "/app/home/views.py", line 41, in get
    "stock": self.get_finance_data("ETH-USD"),
  File "/app/home/views.py", line 48, in get_finance_data
    df["Date"] = df["Date"].dt.strftime("%m/%d")
  File "/usr/local/lib/python3.8/site-packages/pandas/core/generic.py", line 5989, in __getattr__
    return object.__getattribute__(self, name)
  File "/usr/local/lib/python3.8/site-packages/pandas/core/accessor.py", line 224, in __get__
    accessor_obj = self._accessor(obj)
  File "/usr/local/lib/python3.8/site-packages/pandas/core/indexes/accessors.py", line 580, in __new__
    raise AttributeError("Can only use .dt accessor with datetimelike values")
AttributeError: Can only use .dt accessor with datetimelike values
ERROR 2024-09-12 14:34:03,414 django.request.log_response:241- Internal Server Error: /
Traceback (most recent call last):
  File "/usr/local/lib/python3.8/site-packages/django/core/handlers/exception.py", line 55, in inner
    response = get_response(request)
  File "/usr/local/lib/python3.8/site-packages/django/core/handlers/base.py", line 197, in _get_response
    response = wrapped_callback(request, *callback_args, **callback_kwargs)
  File "/usr/local/lib/python3.8/site-packages/django/views/generic/base.py", line 104, in view
    return self.dispatch(request, *args, **kwargs)
  File "/usr/local/lib/python3.8/site-packages/django/views/generic/base.py", line 143, in dispatch
    return handler(request, *args, **kwargs)
  File "/app/home/views.py", line 41, in get
    "stock": self.get_finance_data("ETH-USD"),
  File "/app/home/views.py", line 48, in get_finance_data
    df["Date"] = df["Date"].dt.strftime("%m/%d")
  File "/usr/local/lib/python3.8/site-packages/pandas/core/generic.py", line 5989, in __getattr__
    return object.__getattribute__(self, name)
  File "/usr/local/lib/python3.8/site-packages/pandas/core/accessor.py", line 224, in __get__
    accessor_obj = self._accessor(obj)
  File "/usr/local/lib/python3.8/site-packages/pandas/core/indexes/accessors.py", line 580, in __new__
    raise AttributeError("Can only use .dt accessor with datetimelike values")
AttributeError: Can only use .dt accessor with datetimelike values
WARNING 2024-09-12 14:34:25,651 django.request.log_response:241- Not Found: /favicon.ico
ERROR 2024-09-12 14:34:45,238 django.request.log_response:241- Internal Server Error: /
Traceback (most recent call last):
  File "/usr/local/lib/python3.8/site-packages/django/core/handlers/exception.py", line 55, in inner
    response = get_response(request)
  File "/usr/local/lib/python3.8/site-packages/django/core/handlers/base.py", line 197, in _get_response
    response = wrapped_callback(request, *callback_args, **callback_kwargs)
  File "/usr/local/lib/python3.8/site-packages/django/views/generic/base.py", line 104, in view
    return self.dispatch(request, *args, **kwargs)
  File "/usr/local/lib/python3.8/site-packages/django/views/generic/base.py", line 143, in dispatch
    return handler(request, *args, **kwargs)
  File "/app/home/views.py", line 41, in get
    "stock": self.get_finance_data("ETH-USD"),
  File "/app/home/views.py", line 48, in get_finance_data
    df["Date"] = df["Date"].dt.strftime("%m/%d")
  File "/usr/local/lib/python3.8/site-packages/pandas/core/generic.py", line 5989, in __getattr__
    return object.__getattribute__(self, name)
  File "/usr/local/lib/python3.8/site-packages/pandas/core/accessor.py", line 224, in __get__
    accessor_obj = self._accessor(obj)
  File "/usr/local/lib/python3.8/site-packages/pandas/core/indexes/accessors.py", line 580, in __new__
    raise AttributeError("Can only use .dt accessor with datetimelike values")
AttributeError: Can only use .dt accessor with datetimelike values
ERROR 2024-09-12 14:35:01,920 django.request.log_response:241- Internal Server Error: /
Traceback (most recent call last):
  File "/usr/local/lib/python3.8/site-packages/django/core/handlers/exception.py", line 55, in inner
    response = get_response(request)
  File "/usr/local/lib/python3.8/site-packages/django/core/handlers/base.py", line 197, in _get_response
    response = wrapped_callback(request, *callback_args, **callback_kwargs)
  File "/usr/local/lib/python3.8/site-packages/django/views/generic/base.py", line 104, in view
    return self.dispatch(request, *args, **kwargs)
  File "/usr/local/lib/python3.8/site-packages/django/views/generic/base.py", line 143, in dispatch
    return handler(request, *args, **kwargs)
  File "/app/home/views.py", line 41, in get
    "stock": self.get_finance_data("ETH-USD"),
  File "/app/home/views.py", line 48, in get_finance_data
    df["Date"] = df["Date"].dt.strftime("%m/%d")
  File "/usr/local/lib/python3.8/site-packages/pandas/core/generic.py", line 5989, in __getattr__
    return object.__getattribute__(self, name)
  File "/usr/local/lib/python3.8/site-packages/pandas/core/accessor.py", line 224, in __get__
    accessor_obj = self._accessor(obj)
  File "/usr/local/lib/python3.8/site-packages/pandas/core/indexes/accessors.py", line 580, in __new__
    raise AttributeError("Can only use .dt accessor with datetimelike values")
AttributeError: Can only use .dt accessor with datetimelike values
WARNING 2024-09-12 14:35:24,347 django.request.log_response:241- Not Found: /favicon.ico
ERROR 2024-09-12 14:35:25,965 django.request.log_response:241- Internal Server Error: /
Traceback (most recent call last):
  File "/usr/local/lib/python3.8/site-packages/django/core/handlers/exception.py", line 55, in inner
    response = get_response(request)
  File "/usr/local/lib/python3.8/site-packages/django/core/handlers/base.py", line 197, in _get_response
    response = wrapped_callback(request, *callback_args, **callback_kwargs)
  File "/usr/local/lib/python3.8/site-packages/django/views/generic/base.py", line 104, in view
    return self.dispatch(request, *args, **kwargs)
  File "/usr/local/lib/python3.8/site-packages/django/views/generic/base.py", line 143, in dispatch
    return handler(request, *args, **kwargs)
  File "/app/home/views.py", line 41, in get
    "stock": self.get_finance_data("ETH-USD"),
  File "/app/home/views.py", line 48, in get_finance_data
    df["Date"] = df["Date"].dt.strftime("%m/%d")
  File "/usr/local/lib/python3.8/site-packages/pandas/core/generic.py", line 5989, in __getattr__
    return object.__getattribute__(self, name)
  File "/usr/local/lib/python3.8/site-packages/pandas/core/accessor.py", line 224, in __get__
    accessor_obj = self._accessor(obj)
  File "/usr/local/lib/python3.8/site-packages/pandas/core/indexes/accessors.py", line 580, in __new__
    raise AttributeError("Can only use .dt accessor with datetimelike values")
AttributeError: Can only use .dt accessor with datetimelike values
WARNING 2024-09-12 14:35:28,150 django.request.log_response:241- Not Found: /favicon.ico
ERROR 2024-09-12 14:35:30,556 django.request.log_response:241- Internal Server Error: /
Traceback (most recent call last):
  File "/usr/local/lib/python3.8/site-packages/django/core/handlers/exception.py", line 55, in inner
    response = get_response(request)
  File "/usr/local/lib/python3.8/site-packages/django/core/handlers/base.py", line 197, in _get_response
    response = wrapped_callback(request, *callback_args, **callback_kwargs)
  File "/usr/local/lib/python3.8/site-packages/django/views/generic/base.py", line 104, in view
    return self.dispatch(request, *args, **kwargs)
  File "/usr/local/lib/python3.8/site-packages/django/views/generic/base.py", line 143, in dispatch
    return handler(request, *args, **kwargs)
  File "/app/home/views.py", line 41, in get
    "stock": self.get_finance_data("ETH-USD"),
  File "/app/home/views.py", line 48, in get_finance_data
    df["Date"] = df["Date"].dt.strftime("%m/%d")
  File "/usr/local/lib/python3.8/site-packages/pandas/core/generic.py", line 5989, in __getattr__
    return object.__getattribute__(self, name)
  File "/usr/local/lib/python3.8/site-packages/pandas/core/accessor.py", line 224, in __get__
    accessor_obj = self._accessor(obj)
  File "/usr/local/lib/python3.8/site-packages/pandas/core/indexes/accessors.py", line 580, in __new__
    raise AttributeError("Can only use .dt accessor with datetimelike values")
AttributeError: Can only use .dt accessor with datetimelike values
ERROR 2024-09-12 14:36:06,262 django.request.log_response:241- Internal Server Error: /
Traceback (most recent call last):
  File "/usr/local/lib/python3.8/site-packages/django/core/handlers/exception.py", line 55, in inner
    response = get_response(request)
  File "/usr/local/lib/python3.8/site-packages/django/core/handlers/base.py", line 197, in _get_response
    response = wrapped_callback(request, *callback_args, **callback_kwargs)
  File "/usr/local/lib/python3.8/site-packages/django/views/generic/base.py", line 104, in view
    return self.dispatch(request, *args, **kwargs)
  File "/usr/local/lib/python3.8/site-packages/django/views/generic/base.py", line 143, in dispatch
    return handler(request, *args, **kwargs)
  File "/app/home/views.py", line 41, in get
    "stock": self.get_finance_data("ETH-USD"),
  File "/app/home/views.py", line 48, in get_finance_data
    df["Date"] = df["Date"].dt.strftime("%m/%d")
  File "/usr/local/lib/python3.8/site-packages/pandas/core/generic.py", line 5989, in __getattr__
    return object.__getattribute__(self, name)
  File "/usr/local/lib/python3.8/site-packages/pandas/core/accessor.py", line 224, in __get__
    accessor_obj = self._accessor(obj)
  File "/usr/local/lib/python3.8/site-packages/pandas/core/indexes/accessors.py", line 580, in __new__
    raise AttributeError("Can only use .dt accessor with datetimelike values")
AttributeError: Can only use .dt accessor with datetimelike values
WARNING 2024-09-12 14:42:47,371 django.request.log_response:241- Not Found: /favicon.ico
WARNING 2024-09-12 14:57:36,302 django.request.log_response:241- Not Found: /favicon.ico
WARNING 2024-09-12 15:26:18,031 django.request.log_response:241- Not Found: /favicon.ico
WARNING 2024-09-12 15:28:17,186 django.request.log_response:241- Not Found: /favicon.ico
WARNING 2024-09-12 15:57:40,918 django.request.log_response:241- Not Found: /9999
WARNING 2024-09-12 15:57:43,918 django.request.log_response:241- Not Found: /9999
WARNING 2024-09-12 15:57:56,798 django.request.log_response:241- Not Found: /henlo fren
WARNING 2024-09-12 15:58:02,576 django.request.log_response:241- Not Found: /henlo fren/amogus
WARNING 2024-09-12 15:58:20,963 django.request.log_response:241- Not Found: /admin/999
WARNING 2024-09-12 15:58:32,125 django.request.log_response:241- Not Found: /admin/he
WARNING 2024-09-13 04:42:10,894 django.request.log_response:241- Not Found: /favicon.ico
WARNING 2024-09-13 04:42:20,565 django.request.log_response:241- Not Found: /favicon.ico
WARNING 2024-09-13 05:02:19,142 django.request.log_response:241- Not Found: /favicon.ico
WARNING 2024-09-13 05:02:19,144 django.channels.server.log_action:176- HTTP GET /favicon.ico 404 [0.05, 172.19.0.1:33352]
WARNING 2024-09-13 05:03:57,960 django.request.log_response:241- Not Found: /favicon.ico
WARNING 2024-09-13 05:03:57,961 django.channels.server.log_action:176- HTTP GET /favicon.ico 404 [0.07, 172.19.0.1:46170]
WARNING 2024-09-13 05:08:27,776 django.request.log_response:241- Not Found: /favicon.ico
WARNING 2024-09-13 07:26:14,035 django.request.log_response:241- Not Found: /favicon.ico
WARNING 2024-09-13 07:27:30,451 django.request.log_response:241- Not Found: /favicon.ico
WARNING 2024-09-13 07:27:30,452 django.channels.server.log_action:176- HTTP GET /favicon.ico 404 [0.05, 172.19.0.1:52558]
WARNING 2024-09-13 07:29:12,200 django.request.log_response:241- Not Found: /favicon.ico
WARNING 2024-09-13 07:29:12,201 django.channels.server.log_action:176- HTTP GET /favicon.ico 404 [0.06, 172.19.0.1:47214]
WARNING 2024-09-13 14:24:39,031 django.request.log_response:241- Not Found: /favicon.ico
WARNING 2024-09-13 14:25:11,020 django.request.log_response:241- Not Found: /favicon.ico
WARNING 2024-09-14 05:07:11,405 django.request.log_response:241- Not Found: /favicon.ico
WARNING 2024-09-14 14:41:01,301 django.request.log_response:241- Not Found: /favicon.ico
WARNING 2024-09-14 14:42:36,819 django.request.log_response:241- Not Found: /favicon.ico
WARNING 2024-09-15 05:34:52,234 django.request.log_response:241- Not Found: /favicon.ico
WARNING 2024-09-15 05:38:18,014 django.request.log_response:241- Not Found: /favicon.ico
WARNING 2024-09-15 05:38:29,718 django.request.log_response:241- Not Found: /favicon.ico
WARNING 2024-09-15 05:40:25,928 django.request.log_response:241- Not Found: /favicon.ico
WARNING 2024-09-15 05:40:32,829 django.request.log_response:241- Not Found: /favicon.ico
WARNING 2024-09-15 05:41:16,464 django.request.log_response:241- Not Found: /favicon.ico
WARNING 2024-09-15 05:41:20,314 django.request.log_response:241- Not Found: /favicon.ico
WARNING 2024-09-15 05:42:47,886 django.request.log_response:241- Not Found: /favicon.ico
WARNING 2024-09-15 05:42:51,526 django.request.log_response:241- Not Found: /favicon.ico
WARNING 2024-09-15 05:43:34,816 django.request.log_response:241- Not Found: /favicon.ico
WARNING 2024-09-15 05:43:42,100 django.request.log_response:241- Not Found: /favicon.ico
WARNING 2024-09-15 05:45:31,485 django.request.log_response:241- Not Found: /favicon.ico
WARNING 2024-09-15 05:50:57,049 django.request.log_response:241- Not Found: /favicon.ico
WARNING 2024-09-15 05:56:02,392 django.request.log_response:241- Not Found: /favicon.ico
WARNING 2024-09-15 06:01:30,902 django.request.log_response:241- Not Found: /favicon.ico
WARNING 2024-09-15 06:07:37,517 django.request.log_response:241- Not Found: /favicon.ico
WARNING 2024-09-15 06:12:31,000 django.request.log_response:241- Not Found: /favicon.ico
WARNING 2024-09-15 06:12:35,649 django.request.log_response:241- Not Found: /favicon.ico
WARNING 2024-09-15 06:15:25,835 django.request.log_response:241- Not Found: /favicon.ico
WARNING 2024-09-15 06:16:11,776 django.request.log_response:241- Not Found: /favicon.ico
